{
  "cve": {
    "data_type": "CVE",
    "data_format": "MITRE",
    "data_version": "4.0",
    "CVE_data_meta": {
      "ID": "CVE-2021-28861",
      "ASSIGNER": "cve@mitre.org"
    },
    "problemtype": {
      "problemtype_data": [
        {
          "description": [

          ]
        }
      ]
    },
    "references": {
      "reference_data": [
        {
          "url": "https://github.com/python/cpython/pull/93879",
          "name": "https://github.com/python/cpython/pull/93879",
          "refsource": "MISC",
          "tags": [

          ]
        },
        {
          "url": "https://bugs.python.org/issue43223",
          "name": "https://bugs.python.org/issue43223",
          "refsource": "MISC",
          "tags": [

          ]
        },
        {
          "url": "https://github.com/python/cpython/pull/24848",
          "name": "https://github.com/python/cpython/pull/24848",
          "refsource": "MISC",
          "tags": [

          ]
        }
      ]
    },
    "description": {
      "description_data": [
        {
          "lang": "en",
          "value": "Python 3.x through 3.10 has an open redirection vulnerability in lib/http/server.py due to no protection against multiple (/) at the beginning of URI path which may leads to information disclosure."
        }
      ]
    }
  },
  "configurations": {
    "CVE_data_version": "4.0",
    "nodes": [

    ]
  },
  "impact": {
  },
  "publishedDate": "2022-08-23T01:15Z",
  "lastModifiedDate": "2022-08-23T01:15Z"
}