{
  "cve": {
    "data_type": "CVE",
    "data_format": "MITRE",
    "data_version": "4.0",
    "CVE_data_meta": {
      "ID": "CVE-2024-45230",
      "ASSIGNER": "cve@mitre.org"
    },
    "problemtype": {
      "problemtype_data": [
        {
          "description": [

          ]
        }
      ]
    },
    "references": {
      "reference_data": [
        {
          "url": "https://docs.djangoproject.com/en/dev/releases/security/",
          "name": "https://docs.djangoproject.com/en/dev/releases/security/",
          "refsource": "",
          "tags": [

          ]
        },
        {
          "url": "https://groups.google.com/forum/#%21forum/django-announce",
          "name": "https://groups.google.com/forum/#%21forum/django-announce",
          "refsource": "",
          "tags": [

          ]
        },
        {
          "url": "https://www.djangoproject.com/weblog/2024/sep/03/security-releases/",
          "name": "https://www.djangoproject.com/weblog/2024/sep/03/security-releases/",
          "refsource": "",
          "tags": [

          ]
        }
      ]
    },
    "description": {
      "description_data": [
        {
          "lang": "en",
          "value": "An issue was discovered in Django 5.1 before 5.1.1, 5.0 before 5.0.9, and 4.2 before 4.2.16. The urlize() and urlizetrunc() template filters are subject to a potential denial-of-service attack via very large inputs with a specific sequence of characters."
        }
      ]
    }
  },
  "configurations": {
    "CVE_data_version": "4.0",
    "nodes": [

    ]
  },
  "impact": {
  },
  "publishedDate": "2024-10-08T16:15Z",
  "lastModifiedDate": "2024-10-10T12:56Z"
}